Workbook

Sheet 요약
A1: book-agent 테스트 결과 보고서 (단위 · 실제 API · CLI 통합)
A2: 테스트 시나리오와 실행 결과. 아래 집계는 모두 '시나리오' 시트를 참조하는 수식이라 결과 값을 고치면 자동으로 다시 계산된다.
A4: 실행 시작 | B4: 2026-10-27 14:02:32
A5: 실행 종료 | B5: 2026-10-27 14:23:44
A6: 실행 명령 | B6: pytest --live -q -p no:cacheprovider --scenario-report=docs/unit_test_results.json ; pytest tests/test_integration.py --live -q -p no:cacheprovider --scenario-report=docs/integration_test_results.json ; pytest -q -p no:cacheprovider --scenario-report=docs/unit_only_results.json
A7: pytest 종료 코드 | B7: 1 (0 = 전체 통과)
A8: 총 소요 시간(초) | B8: =SUM(시나리오!$L$2:$L$204)
A10: 전체 결과
A11: 전체 | B11: PASS | C11: FAIL | D11: ERROR | E11: SKIP | F11: 통과율
A12: =COUNTA(시나리오!$K$2:$K$204) | B12: =COUNTIF(시나리오!$K$2:$K$204,"PASS") | C12: =COUNTIF(시나리오!$K$2:$K$204,"FAIL") | D12: =COUNTIF(시나리오!$K$2:$K$204,"ERROR") | E12: =COUNTIF(시나리오!$K$2:$K$204,"SKIP") | F12: =IF(A12-E12=0,"-",B12/(A12-E12))
A13: 통과율 = PASS / (전체 - SKIP). SKIP 은 실행 조건(GPU 등)이 맞지 않아 건너뛴 시나리오.
A15: 모듈별 결과
A16: 모듈 | B16: 대상 | C16: 시나리오 수 | D16: PASS | E16: FAIL | F16: ERROR | G16: SKIP | H16: 통과율 | I16: 소요(초)
A17: ENV | B17: 실행 환경 (Python, .env, CUDA) | C17: =COUNTIF(시나리오!$B$2:$B$204,A17) | D17: =COUNTIFS(시나리오!$B$2:$B$204,A17,시나리오!$K$2:$K$204,"PASS") | E17: =COUNTIFS(시나리오!$B$2:$B$204,A17,시나리오!$K$2:$K$204,"FAIL") | F17: =COUNTIFS(시나리오!$B$2:$B$204,A17,시나리오!$K$2:$K$204,"ERROR") | G17: =COUNTIFS(시나리오!$B$2:$B$204,A17,시나리오!$K$2:$K$204,"SKIP") | H17: =IF(C17-G17=0,"-",D17/(C17-G17)) | I17: =SUMIF(시나리오!$B$2:$B$204,A17,시나리오!$L$2:$L$204)
A18: SET | B18: settings.py / device.py | C18: =COUNTIF(시나리오!$B$2:$B$204,A18) | D18: =COUNTIFS(시나리오!$B$2:$B$204,A18,시나리오!$K$2:$K$204,"PASS") | E18: =COUNTIFS(시나리오!$B$2:$B$204,A18,시나리오!$K$2:$K$204,"FAIL") | F18: =COUNTIFS(시나리오!$B$2:$B$204,A18,시나리오!$K$2:$K$204,"ERROR") | G18: =COUNTIFS(시나리오!$B$2:$B$204,A18,시나리오!$K$2:$K$204,"SKIP") | H18: =IF(C18-G18=0,"-",D18/(C18-G18)) | I18: =SUMIF(시나리오!$B$2:$B$204,A18,시나리오!$L$2:$L$204)
A19: MOD | B19: models.py / state.py | C19: =COUNTIF(시나리오!$B$2:$B$204,A19) | D19: =COUNTIFS(시나리오!$B$2:$B$204,A19,시나리오!$K$2:$K$204,"PASS") | E19: =COUNTIFS(시나리오!$B$2:$B$204,A19,시나리오!$K$2:$K$204,"FAIL") | F19: =COUNTIFS(시나리오!$B$2:$B$204,A19,시나리오!$K$2:$K$204,"ERROR") | G19: =COUNTIFS(시나리오!$B$2:$B$204,A19,시나리오!$K$2:$K$204,"SKIP") | H19: =IF(C19-G19=0,"-",D19/(C19-G19)) | I19: =SUMIF(시나리오!$B$2:$B$204,A19,시나리오!$L$2:$L$204)
A20: REP | B20: repositories.py | C20: =COUNTIF(시나리오!$B$2:$B$204,A20) | D20: =COUNTIFS(시나리오!$B$2:$B$204,A20,시나리오!$K$2:$K$204,"PASS") | E20: =COUNTIFS(시나리오!$B$2:$B$204,A20,시나리오!$K$2:$K$204,"FAIL") | F20: =COUNTIFS(시나리오!$B$2:$B$204,A20,시나리오!$K$2:$K$204,"ERROR") | G20: =COUNTIFS(시나리오!$B$2:$B$204,A20,시나리오!$K$2:$K$204,"SKIP") | H20: =IF(C20-G20=0,"-",D20/(C20-G20)) | I20: =SUMIF(시나리오!$B$2:$B$204,A20,시나리오!$L$2:$L$204)
A21: ERR | B21: errors.py | C21: =COUNTIF(시나리오!$B$2:$B$204,A21) | D21: =COUNTIFS(시나리오!$B$2:$B$204,A21,시나리오!$K$2:$K$204,"PASS") | E21: =COUNTIFS(시나리오!$B$2:$B$204,A21,시나리오!$K$2:$K$204,"FAIL") | F21: =COUNTIFS(시나리오!$B$2:$B$204,A21,시나리오!$K$2:$K$204,"ERROR") | G21: =COUNTIFS(시나리오!$B$2:$B$204,A21,시나리오!$K$2:$K$204,"SKIP") | H21: =IF(C21-G21=0,"-",D21/(C21-G21)) | I21: =SUMIF(시나리오!$B$2:$B$204,A21,시나리오!$L$2:$L$204)
A22: SVC | B22: services.py | C22: =COUNTIF(시나리오!$B$2:$B$204,A22) | D22: =COUNTIFS(시나리오!$B$2:$B$204,A22,시나리오!$K$2:$K$204,"PASS") | E22: =COUNTIFS(시나리오!$B$2:$B$204,A22,시나리오!$K$2:$K$204,"FAIL") | F22: =COUNTIFS(시나리오!$B$2:$B$204,A22,시나리오!$K$2:$K$204,"ERROR") | G22: =COUNTIFS(시나리오!$B$2:$B$204,A22,시나리오!$K$2:$K$204,"SKIP") | H22: =IF(C22-G22=0,"-",D22/(C22-G22)) | I22: =SUMIF(시나리오!$B$2:$B$204,A22,시나리오!$L$2:$L$204)
A23: TOL | B23: tools.py | C23: =COUNTIF(시나리오!$B$2:$B$204,A23) | D23: =COUNTIFS(시나리오!$B$2:$B$204,A23,시나리오!$K$2:$K$204,"PASS") | E23: =COUNTIFS(시나리오!$B$2:$B$204,A23,시나리오!$K$2:$K$204,"FAIL") | F23: =COUNTIFS(시나리오!$B$2:$B$204,A23,시나리오!$K$2:$K$204,"ERROR") | G23: =COUNTIFS(시나리오!$B$2:$B$204,A23,시나리오!$K$2:$K$204,"SKIP") | H23: =IF(C23-G23=0,"-",D23/(C23-G23)) | I23: =SUMIF(시나리오!$B$2:$B$204,A23,시나리오!$L$2:$L$204)
A24: NOD | B24: nodes.py | C24: =COUNTIF(시나리오!$B$2:$B$204,A24) | D24: =COUNTIFS(시나리오!$B$2:$B$204,A24,시나리오!$K$2:$K$204,"PASS") | E24: =COUNTIFS(시나리오!$B$2:$B$204,A24,시나리오!$K$2:$K$204,"FAIL") | F24: =COUNTIFS(시나리오!$B$2:$B$204,A24,시나리오!$K$2:$K$204,"ERROR") | G24: =COUNTIFS(시나리오!$B$2:$B$204,A24,시나리오!$K$2:$K$204,"SKIP") | H24: =IF(C24-G24=0,"-",D24/(C24-G24)) | I24: =SUMIF(시나리오!$B$2:$B$204,A24,시나리오!$L$2:$L$204)
A25: GRP | B25: graph.py | C25: =COUNTIF(시나리오!$B$2:$B$204,A25) | D25: =COUNTIFS(시나리오!$B$2:$B$204,A25,시나리오!$K$2:$K$204,"PASS") | E25: =COUNTIFS(시나리오!$B$2:$B$204,A25,시나리오!$K$2:$K$204,"FAIL") | F25: =COUNTIFS(시나리오!$B$2:$B$204,A25,시나리오!$K$2:$K$204,"ERROR") | G25: =COUNTIFS(시나리오!$B$2:$B$204,A25,시나리오!$K$2:$K$204,"SKIP") | H25: =IF(C25-G25=0,"-",D25/(C25-G25)) | I25: =SUMIF(시나리오!$B$2:$B$204,A25,시나리오!$L$2:$L$204)
A26: APP | B26: app.py / __init__.py | C26: =COUNTIF(시나리오!$B$2:$B$204,A26) | D26: =COUNTIFS(시나리오!$B$2:$B$204,A26,시나리오!$K$2:$K$204,"PASS") | E26: =COUNTIFS(시나리오!$B$2:$B$204,A26,시나리오!$K$2:$K$204,"FAIL") | F26: =COUNTIFS(시나리오!$B$2:$B$204,A26,시나리오!$K$2:$K$204,"ERROR") | G26: =COUNTIFS(시나리오!$B$2:$B$204,A26,시나리오!$K$2:$K$204,"SKIP") | H26: =IF(C26-G26=0,"-",D26/(C26-G26)) | I26: =SUMIF(시나리오!$B$2:$B$204,A26,시나리오!$L$2:$L$204)
A27: LIV | B27: 실제 API 통합 (OpenAI, Tavily) | C27: =COUNTIF(시나리오!$B$2:$B$204,A27) | D27: =COUNTIFS(시나리오!$B$2:$B$204,A27,시나리오!$K$2:$K$204,"PASS") | E27: =COUNTIFS(시나리오!$B$2:$B$204,A27,시나리오!$K$2:$K$204,"FAIL") | F27: =COUNTIFS(시나리오!$B$2:$B$204,A27,시나리오!$K$2:$K$204,"ERROR") | G27: =COUNTIFS(시나리오!$B$2:$B$204,A27,시나리오!$K$2:$K$204,"SKIP") | H27: =IF(C27-G27=0,"-",D27/(C27-G27)) | I27: =SUMIF(시나리오!$B$2:$B$204,A27,시나리오!$L$2:$L$204)
A28: INT | B28: CLI 통합 (book-agent 프로세스) | C28: =COUNTIF(시나리오!$B$2:$B$204,A28) | D28: =COUNTIFS(시나리오!$B$2:$B$204,A28,시나리오!$K$2:$K$204,"PASS") | E28: =COUNTIFS(시나리오!$B$2:$B$204,A28,시나리오!$K$2:$K$204,"FAIL") | F28: =COUNTIFS(시나리오!$B$2:$B$204,A28,시나리오!$K$2:$K$204,"ERROR") | G28: =COUNTIFS(시나리오!$B$2:$B$204,A28,시나리오!$K$2:$K$204,"SKIP") | H28: =IF(C28-G28=0,"-",D28/(C28-G28)) | I28: =SUMIF(시나리오!$B$2:$B$204,A28,시나리오!$L$2:$L$204)
A29: 합계 | C29: =SUM(C17:C28) | D29: =SUM(D17:D28) | E29: =SUM(E17:E28) | F29: =SUM(F17:F28) | G29: =SUM(G17:G28) | H29: =IF(C29-G29=0,"-",D29/(C29-G29)) | I29: =SUM(I17:I28)
A31: 구분별 결과
A32: 항목 | C32: 시나리오 수 | D32: PASS | E32: FAIL | F32: ERROR | G32: SKIP | H32: 통과율
A33: 정상 | C33: =COUNTIF(시나리오!$E$2:$E$204,A33) | D33: =COUNTIFS(시나리오!$E$2:$E$204,A33,시나리오!$K$2:$K$204,"PASS") | E33: =COUNTIFS(시나리오!$E$2:$E$204,A33,시나리오!$K$2:$K$204,"FAIL") | F33: =COUNTIFS(시나리오!$E$2:$E$204,A33,시나리오!$K$2:$K$204,"ERROR") | G33: =COUNTIFS(시나리오!$E$2:$E$204,A33,시나리오!$K$2:$K$204,"SKIP") | H33: =IF(C33-G33=0,"-",D33/(C33-G33))
A34: 예외 | C34: =COUNTIF(시나리오!$E$2:$E$204,A34) | D34: =COUNTIFS(시나리오!$E$2:$E$204,A34,시나리오!$K$2:$K$204,"PASS") | E34: =COUNTIFS(시나리오!$E$2:$E$204,A34,시나리오!$K$2:$K$204,"FAIL") | F34: =COUNTIFS(시나리오!$E$2:$E$204,A34,시나리오!$K$2:$K$204,"ERROR") | G34: =COUNTIFS(시나리오!$E$2:$E$204,A34,시나리오!$K$2:$K$204,"SKIP") | H34: =IF(C34-G34=0,"-",D34/(C34-G34))
A35: 경계 | C35: =COUNTIF(시나리오!$E$2:$E$204,A35) | D35: =COUNTIFS(시나리오!$E$2:$E$204,A35,시나리오!$K$2:$K$204,"PASS") | E35: =COUNTIFS(시나리오!$E$2:$E$204,A35,시나리오!$K$2:$K$204,"FAIL") | F35: =COUNTIFS(시나리오!$E$2:$E$204,A35,시나리오!$K$2:$K$204,"ERROR") | G35: =COUNTIFS(시나리오!$E$2:$E$204,A35,시나리오!$K$2:$K$204,"SKIP") | H35: =IF(C35-G35=0,"-",D35/(C35-G35))
A37: 우선순위별 결과
A38: 항목 | C38: 시나리오 수 | D38: PASS | E38: FAIL | F38: ERROR | G38: SKIP | H38: 통과율
A39: 상 | C39: =COUNTIF(시나리오!$F$2:$F$204,A39) | D39: =COUNTIFS(시나리오!$F$2:$F$204,A39,시나리오!$K$2:$K$204,"PASS") | E39: =COUNTIFS(시나리오!$F$2:$F$204,A39,시나리오!$K$2:$K$204,"FAIL") | F39: =COUNTIFS(시나리오!$F$2:$F$204,A39,시나리오!$K$2:$K$204,"ERROR") | G39: =COUNTIFS(시나리오!$F$2:$F$204,A39,시나리오!$K$2:$K$204,"SKIP") | H39: =IF(C39-G39=0,"-",D39/(C39-G39))
A40: 중 | C40: =COUNTIF(시나리오!$F$2:$F$204,A40) | D40: =COUNTIFS(시나리오!$F$2:$F$204,A40,시나리오!$K$2:$K$204,"PASS") | E40: =COUNTIFS(시나리오!$F$2:$F$204,A40,시나리오!$K$2:$K$204,"FAIL") | F40: =COUNTIFS(시나리오!$F$2:$F$204,A40,시나리오!$K$2:$K$204,"ERROR") | G40: =COUNTIFS(시나리오!$F$2:$F$204,A40,시나리오!$K$2:$K$204,"SKIP") | H40: =IF(C40-G40=0,"-",D40/(C40-G40))
A41: 하 | C41: =COUNTIF(시나리오!$F$2:$F$204,A41) | D41: =COUNTIFS(시나리오!$F$2:$F$204,A41,시나리오!$K$2:$K$204,"PASS") | E41: =COUNTIFS(시나리오!$F$2:$F$204,A41,시나리오!$K$2:$K$204,"FAIL") | F41: =COUNTIFS(시나리오!$F$2:$F$204,A41,시나리오!$K$2:$K$204,"ERROR") | G41: =COUNTIFS(시나리오!$F$2:$F$204,A41,시나리오!$K$2:$K$204,"SKIP") | H41: =IF(C41-G41=0,"-",D41/(C41-G41))
A43: 구분 정의
A44: 정상: 기대한 입력에서 기능이 올바르게 동작하는지
A45: 예외: 잘못된 입력·외부 오류에서 안전하게 실패/복구하는지
A46: 경계: 한도·빈 값·중복 등 경계 조건에서 동작하는지
...

Sheet 시나리오
A1: ID | B1: 모듈 | C1: 테스트 파일 | D1: 테스트 대상 | E1: 구분 | F1: 우선순위 | G1: 시나리오 | H1: 사전조건 | I1: 절차 | J1: 기대결과 | K1: 결과 | L1: 소요(초) | M1: 비고(실패/스킵 사유) | N1: 테스트 함수
A2: ENV-01 | B2: ENV | C2: test_environment.py | D2: 실행 환경 | E2: 정상 | F2: 상 | G2: 프로젝트가 요구하는 Python 버전에서 실행된다. | H2: uv 가상환경(.venv)으로 pytest 실행 | I2: sys.version_info 의 major/minor 확인 | J2: (3, 12) | K2: PASS | L2: 0.001 | N2: tests/test_environment.py::test_python_version
A3: ENV-02 | B3: ENV | C3: test_environment.py | D3: settings.load_settings | E3: 정상 | F3: 상 | G3: .env 의 값이 Settings 필드와 os.environ 양쪽으로 전달된다. | H3: OPENAI_API_KEY, TAVILY_API_KEY, HF_TOKEN, LLM_MODEL 환경변수 제거 | I3: 1) 임시 .env 에 4개 값 기록 2) load_settings(.env 경로) 호출 | J3: 비밀값/모델명이 Settings 에 들어가고, Settings 에 없는 HF_TOKEN 은 os.environ 에 올라간다 | K3: PASS | L3: 0.007 | N3: tests/test_environment.py::test_settings_and_env_passthrough
A4: ENV-03 | B4: ENV | C4: test_environment.py | D4: settings.load_settings | E4: 예외 | F4: 상 | G4: 필수 API 키가 없으면 시작 시점에 바로 실패한다. | H4: OPENAI_API_KEY 환경변수 제거 | I4: LLM_MODEL 만 있는 .env 로 load_settings 호출 | J4: openai_api_key 를 언급하는 ValidationError(ValueError) | K4: PASS | L4: 0.006 | N4: tests/test_environment.py::test_missing_key_fails_fast
A5: ENV-04 | B5: ENV | C5: test_environment.py | D5: device.resolve_device | E5: 정상 | F5: 하 | G5: GPU 가 있는 PC 에서는 auto 장치가 cuda 로 결정되고 실제 연산이 된다. | H5: torch 설치, CUDA 사용 가능(아니면 SKIP) | I5: 1) resolve_device('auto') 2) cuda 텐서로 간단한 연산 | J5: 'cuda' 반환, 연산 결과 4 | K5: PASS | L5: 2.771 | N5: tests/test_environment.py::test_cuda_available
A6: SET-01 | B6: SET | C6: test_settings.py | D6: settings.Settings | E6: 정상 | F6: 중 | G6: 필수 키만 주면 나머지 설정은 문서화된 기본값을 갖는다. | H6: 설정 관련 환경변수 제거, .env 미사용 | I6: API 키 두 개만 넣어 Settings 생성 | J6: llm_model=gpt-5.5, embedding_provider=openai, chunk 1000/100, top_k 5, 조사 한도 2, 도구 호출 한도 6, thread_id=book_001 | K6: PASS | L6: 0.004 | N6: tests/test_settings.py::test_defaults
A7: SET-02 | B7: SET | C7: test_settings.py | D7: settings.Settings 경로 속성 | E7: 정상 | F7: 중 | G7: 저장 경로는 모두 data_dir 아래에 만들어진다. | H7: data_dir=tmp_path | I7: outline_path, chroma_dir, resources_dir, checkpoint_db 조회 | J7: 각각 outline.md, chroma, resources, checkpoints.sqlite | K7: PASS | L7: 0.004 | N7: tests/test_settings.py::test_derived_paths_follow_data_dir
A8: SET-03 | B8: SET | C8: test_settings.py | D8: settings.Settings (SecretStr) | E8: 정상 | F8: 상 | G8: API 키는 출력/로그에 원문이 드러나지 않는다. | H8: openai_api_key='sk-secret-value' | I8: repr(settings), str(settings.openai_api_key) 확인 | J8: 원문 미노출('**********'), get_secret_value() 로만 원문 획득 | K8: PASS | L8: 0.004 | N8: tests/test_settings.py::test_secrets_are_masked
A9: SET-04 | B9: SET | C9: test_settings.py | D9: settings.Settings | E9: 정상 | F9: 중 | G9: 환경변수 값이 기본값보다 우선하고 타입이 변환된다. | H9: LLM_MODEL=custom, SEARCH_TOP_K=9, EMBEDDING_PROVIDER=huggingface 설정 | I9: Settings 생성 | J9: 문자열 '9' 가 int 9 로 변환되어 적용 | K9: PASS | L9: 0.004 | N9: tests/test_settings.py::test_env_vars_override_defaults
A10: SET-05 | B10: SET | C10: test_settings.py | D10: settings.Settings | E10: 예외 | F10: 상 | G10: Tavily 키가 없으면 설정 생성이 실패한다. | H10: TAVILY_API_KEY 환경변수 없음 | I10: tavily_api_key 없이 Settings 생성 | J10: tavily_api_key 를 언급하는 ValidationError | K10: PASS | L10: 0.004 | N10: tests/test_settings.py::test_missing_tavily_key_fails
A11: SET-06 | B11: SET | C11: test_settings.py | D11: settings.Settings 필드 검증 | E11: 경계 | F11: 중 | G11: 범위를 벗어나거나 허용 목록에 없는 설정값은 거부된다. [chunk_size-0] | H11: 없음 | I11: 해당 필드에 잘못된 값을 넣어 Settings 생성 | J11: 해당 필드명을 언급하는 ValidationError | K11: PASS | L11: 0.004 | N11: tests/test_settings.py::test_invalid_values_rejected[chunk_size-0]
A12: SET-07 | B12: SET | C12: test_settings.py | D12: settings.Settings 필드 검증 | E12: 경계 | F12: 중 | G12: 범위를 벗어나거나 허용 목록에 없는 설정값은 거부된다. [chunk_overlap--1] | H12: 없음 | I12: 해당 필드에 잘못된 값을 넣어 Settings 생성 | J12: 해당 필드명을 언급하는 ValidationError | K12: PASS | L12: 0.004 | N12: tests/test_settings.py::test_invalid_values_rejected[chunk_overlap--1]
A13: SET-08 | B13: SET | C13: test_settings.py | D13: settings.Settings 필드 검증 | E13: 경계 | F13: 중 | G13: 범위를 벗어나거나 허용 목록에 없는 설정값은 거부된다. [search_top_k-0] | H13: 없음 | I13: 해당 필드에 잘못된 값을 넣어 Settings 생성 | J13: 해당 필드명을 언급하는 ValidationError | K13: PASS | L13: 0.004 | N13: tests/test_settings.py::test_invalid_values_rejected[search_top_k-0]
... A204: INT-09 | B204: INT | C204: test_integration.py | D204: app.main (EOFError 처리) | E204: 예외 | F204: 하 | G204: 'q' 없이 표준입력이 끝나도 오류 없이 종료한다(API 호출 없음). | H204: 빈 DATA_DIR | I204: 아무 입력 없이 표준입력 종료 | J204: 종료 코드 0, 'Goodbye!!', traceback 미출력 | K204: PASS | L204: 3.819 | N204: tests/test_integration.py::test_cli_stdin_closed_without_quit

Sheet 실행 환경
A1: 항목 | B1: 값
A2: Python | B2: 3.12.10
A3: 플랫폼 | B3: Windows-10-10.0.19045-SP0
A4: 연산 장치 | B4: torch 2.14.1+cu130, CUDA 사용 가능: True
A5: 패키지: pytest | B5: 9.1.1
A6: 패키지: langchain | B6: 1.4.7
A7: 패키지: langchain-core | B7: 1.7.0
A8: 패키지: langgraph | B8: 1.2.16
A9: 패키지: langchain-chroma | B9: 1.1.0
A10: 패키지: pydantic | B10: 2.14.1
A11: 외부 의존성 | B11: OpenAI/Tavily API 는 호출하지 않음(가짜 LLM·검색 클라이언트·임베딩 사용)
A12: 파일 시스템 | B12: 모든 파일은 pytest tmp_path 아래에만 생성
... A14: ID 규칙 | B14: 모듈 코드-일련번호. 매개변수화 테스트는 케이스마다 ID 를 하나씩 부여
